Workbook

Sheet Tasks
A1: Task Name | B1: Owner | C1: Custom Status | D1: Associated Team | E1: Tags | F1: Start Date | G1: Due Date | H1: Duration | I1: Duration Type | J1: Priority | K1: % Completed | L1: Task Description | M1: Work hours | N1: Work Hours Per Owner | O1: Work Hours Unit | P1: Individual Work | Q1: Billing Type | R1: Task List Name | S1: Multi Select | T1: User Pick List All Users | U1: User Pick List Select Users | V1: User Pick List Select Roles | W1: Multi User Select Users | X1: Multi User All Users | Y1: Date & Time | Z1: Date | AA1: Decimal | AB1: Number | AC1: Percentage | AD1: Currency | AE1: Checkbox | AF1: Long URL | AG1: URL | AH1: Phone | AI1: Email | AJ1: Pick List | AK1: Multi-Line | AL1: Single-Line
A2: WL Oct W1 Over-allocated (1 of 2) - Vishal workload | B2: Vishal workload | C2: Open | D2: UIAutomation_Workload_TeamA | E2: wl-over | F2: 05/10/2026 | G2: 09/10/2026 | H2: 5 | I2: days | J2: High | K2: 0 | L2: Workload full coverage [Over-allocated]. Scenario: Over-allocated week, variant a: 6:00/d + 4:30/d. Expected: Vishal workload: 10:30 h/day on 5 working days (116.67% of 9 h). | M2: 30:00 | N2: 06:00 | O2: hrs/day | P2: Vishal workload-06:00 /day | Q2: Billable | R2: WL Oct 2026
A3: WL Oct W1 Over-allocated (2 of 2) - Vishal workload | B3: Vishal workload | C3: In Progress | D3: UIAutomation_Workload_TeamB | E3: wl-over | F3: 05/10/2026 | G3: 09/10/2026 | H3: 5 | I3: days | J3: Medium | K3: 10 | L3: Workload full coverage [Over-allocated]. Scenario: Over-allocated week, variant a: 6:00/d + 4:30/d. Expected: Vishal workload: 10:30 h/day on 5 working days (116.67% of 9 h). | M3: 22:30 | N3: 04:30 | O3: hrs/day | P3: Vishal workload-04:30 /day | Q3: Non Billable | R3: WL Oct 2026 | S3: A | T3: Vishal workload | U3: Vishal workload | V3: Vishal workload | W3: Vishal workload,Vishal PLAdmin | X3: Vishal workload,Vishal PLAdmin | Y3: 01/10/2026 09:30 | Z3: 01/10/2026 | AA3: 1.125 | AB3: 10 | AC3: 25.0 | AD3: 100.00 | AE3: true | AF3: https://projects.zoho.com/portal/workload/cv/1?view=all | AG3: https://www.zoho.com/projects/1 | AH3: 9876543201 | AI3: cv1@example.com | AJ3: 1 | AK3: CV multi line 1 second line | AL3: CV single line 1
A4: WL Oct W2 Optimally allocated - Vishal workload | B4: Vishal workload | C4: In Review | D4: UIAutomation_Workload_TeamB, UIAutomation_Workload_TeamA | E4: wl-optimal | F4: 12/10/2026 | G4: 16/10/2026 | H4: 5 | I4: days | J4: Low | K4: 25 | L4: Workload full coverage [Optimally allocated]. Scenario: Optimally allocated week, variant a: 9:00/d. Expected: Vishal workload: 09:00 h/day on 5 working days (100.00% of 9 h). | M4: 45:00 | N4: 09:00 | O4: hrs/day | P4: Vishal workload-09:00 /day | Q4: None | R4: WL Oct 2026 | S4: B | T4: Vishal PLAdmin | U4: Vishal PLAdmin | V4: Vishal PLAdmin | W4: Vishal PLAdmin | X4: Vishal PLAdmin | Y4: 02/10/2026 10:30 | Z4: 02/10/2026 | AA4: 2.225 | AB4: 20 | AC4: 50.0 | AD4: 200.00 | AE4: false | AF4: https://projects.zoho.com/portal/workload/cv/2?view=all | AG4: https://www.zoho.com/projects/2 | AH4: 9876543202 | AI4: cv2@example.com | AJ4: 2 | AK4: CV multi line 2 second line | AL4: CV single line 2
A5: WL Oct W3 Under-allocated - Vishal workload | B5: Vishal workload | C5: To be Tested | E5: wl-under | F5: 19/10/2026 | G5: 23/10/2026 | H5: 5 | I5: days | J5: None | K5: 50 | L5: Workload full coverage [Under-allocated]. Scenario: Under-allocated week, variant a: 4:30/d. Expected: Vishal workload: 04:30 h/day on 5 working days (50.00% of 9 h). | M5: 22:30 | N5: 04:30 | O5: hrs/day | P5: Vishal workload-04:30 /day | Q5: Billable | R5: WL Oct 2026 | S5: A,B | T5: vishal PL manager | U5: vishal PL manager | V5: vishal PL manager | W5: Vishal workload,Vishal PLAdmin | X5: Vishal workload,Vishal PLAdmin | Y5: 03/10/2026 11:30 | Z5: 03/10/2026 | AA5: 3.325 | AB5: 30 | AC5: 75.0 | AD5: 300.00 | AE5: true | AF5: https://projects.zoho.com/portal/workload/cv/3?view=all | AG5: https://www.zoho.com/projects/3 | AH5: 9876543203 | AI5: cv3@example.com | AJ5: 3 | AK5: CV multi line 3 second line | AL5: CV single line 3
A6: WL Nov W1 Optimally allocated - Vishal workload | B6: Vishal workload | C6: On Hold | D6: UIAutomation_Workload_TeamA | E6: wl-optimal | F6: 02/11/2026 | G6: 06/11/2026 | H6: 5 | I6: days | J6: High | K6: 75 | L6: Workload full coverage [Optimally allocated]. Scenario: Optimally allocated week, variant d: total 9 h/d. Expected: Vishal workload: 09:00 h/day on 5 working days (100.00% of 9 h). | M6: 45:00 | N6: 45:00 | O6: hrs | P6: Vishal workload-45:00 | Q6: Non Billable | R6: WL Nov 2026
A7: WL Nov W2 Under-allocated - Vishal workload | B7: Vishal workload | C7: Delayed | D7: UIAutomation_Workload_TeamB | E7: wl-under | F7: 09/11/2026 | G7: 13/11/2026 | H7: 5 | I7: days | J7: Medium | K7: 90 | L7: Workload full coverage [Under-allocated]. Scenario: Under-allocated week, variant d: 8:30/d. Expected: Vishal workload: 08:30 h/day on 5 working days (94.44% of 9 h). | M7: 42:30 | N7: 08:30 | O7: hrs/day | P7: Vishal workload-08:30 /day | Q7: None | R7: WL Nov 2026 | S7: A | T7: Vishal workload | U7: Vishal workload | V7: Vishal workload | W7: Vishal workload,Vishal PLAdmin | X7: Vishal workload,Vishal PLAdmin | Y7: 01/10/2026 09:30 | Z7: 01/10/2026 | AA7: 1.125 | AB7: 10 | AC7: 25.0 | AD7: 100.00 | AE7: true | AF7: https://projects.zoho.com/portal/workload/cv/1?view=all | AG7: https://www.zoho.com/projects/1 | AH7: 9876543201 | AI7: cv1@example.com | AJ7: 1 | AK7: CV multi line 1 second line | AL7: CV single line 1
A8: WL Nov W3 Unallocated - Vishal workload | B8: Vishal workload | C8: Closed | D8: UIAutomation_Workload_TeamB, UIAutomation_Workload_TeamA | E8: wl-unallocated | F8: 16/11/2026 | G8: 20/11/2026 | H8: 5 | I8: days | J8: Low | K8: 100 | L8: Workload full coverage [Unallocated]. Scenario: Unallocated week, variant d: task with 0:00. Expected: Vishal workload: 00:00 h/day on 5 working days (0.00% of 9 h). | M8: 00:00 | N8: 00:00 | O8: hrs/day | P8: Vishal workload-00:00 /day | Q8: Billable | R8: Workload CV List | S8: B | T8: Vishal PLAdmin | U8: Vishal PLAdmin | V8: Vishal PLAdmin | W8: Vishal PLAdmin | X8: Vishal PLAdmin | Y8: 02/10/2026 10:30 | Z8: 02/10/2026 | AA8: 2.225 | AB8: 20 | AC8: 50.0 | AD8: 200.00 | AE8: false | AF8: https://projects.zoho.com/portal/workload/cv/2?view=all | AG8: https://www.zoho.com/projects/2 | AH8: 9876543202 | AI8: cv2@example.com | AJ8: 2 | AK8: CV multi line 2 second line | AL8: CV single line 2
A9: WL Nov W4 Over-allocated (1 of 2) - Vishal workload | B9: Vishal workload | C9: Cancelled | E9: wl-over | F9: 23/11/2026 | G9: 27/11/2026 | H9: 5 | I9: days | J9: None | K9: 0 | L9: Workload full coverage [Over-allocated]. Scenario: Over-allocated week, variant d: 5:00/d + 50 %/d. Expected: Vishal workload: 09:30 h/day on 5 working days (105.56% of 9 h). | M9: 25:00 | N9: 05:00 | O9: hrs/day | P9: Vishal workload-05:00 /day | Q9: Non Billable | R9: WL Nov 2026 | S9: A,B | T9: vishal PL manager | U9: vishal PL manager | V9: vishal PL manager | W9: Vishal workload,Vishal PLAdmin | X9: Vishal workload,Vishal PLAdmin | Y9: 03/10/2026 11:30 | Z9: 03/10/2026 | AA9: 3.325 | AB9: 30 | AC9: 75.0 | AD9: 300.00 | AE9: true | AF9: https://projects.zoho.com/portal/workload/cv/3?view=all | AG9: https://www.zoho.com/projects/3 | AH9: 9876543203 | AI9: cv3@example.com | AJ9: 3 | AK9: CV multi line 3 second line | AL9: CV single line 3
A10: WL Nov W4 Over-allocated (2 of 2) - Vishal workload | B10: Vishal workload | C10: Open | D10: UIAutomation_Workload_TeamA | E10: wl-over | F10: 23/11/2026 | G10: 27/11/2026 | H10: 5 | I10: days | J10: High | K10: 25 | L10: Workload full coverage [Over-allocated]. Scenario: Over-allocated week, variant d: 5:00/d + 50 %/d. Expected: Vishal workload: 09:30 h/day on 5 working days (105.56% of 9 h). | M10: 22:30 | N10: 50 | O10: %/day | P10: Vishal workload-50 %/day | Q10: None | R10: WL Nov 2026
A11: WL Dec W1 Under-allocated - Vishal workload | B11: Vishal workload | C11: In Progress | D11: UIAutomation_Workload_TeamB | E11: wl-under | F11: 07/12/2026 | G11: 11/12/2026 | H11: 5 | I11: days | J11: Medium | K11: 50 | L11: Workload full coverage [Under-allocated]. Scenario: Under-allocated week, variant c: total 3 h/d. Expected: Vishal workload: 03:00 h/day on 5 working days (33.33% of 9 h). | M11: 15:00 | N11: 15:00 | O11: hrs | P11: Vishal workload-15:00 | Q11: Billable | R11: WL Dec 2026 | S11: A | T11: Vishal workload | U11: Vishal workload | V11: Vishal workload | W11: Vishal workload,Vishal PLAdmin | X11: Vishal workload,Vishal PLAdmin | Y11: 01/10/2026 09:30 | Z11: 01/10/2026 | AA11: 1.125 | AB11: 10 | AC11: 25.0 | AD11: 100.00 | AE11: true | AF11: https://projects.zoho.com/portal/workload/cv/1?view=all | AG11: https://www.zoho.com/projects/1 | AH11: 9876543201 | AI11: cv1@example.com | AJ11: 1 | AK11: CV multi line 1 second line | AL11: CV single line 1
A12: WL Dec W3 Over-allocated - Vishal workload | B12: Vishal workload | C12: In Review | D12: UIAutomation_Workload_TeamB, UIAutomation_Workload_TeamA | E12: wl-over | F12: 21/12/2026 | G12: 25/12/2026 | H12: 5 | I12: days | J12: Low | K12: 75 | L12: Workload full coverage [Over-allocated]. Scenario: Over-allocated week, variant c: total 12 h/d. Expected: Vishal workload: 12:00 h/day on 5 working days (133.33% of 9 h). | M12: 60:00 | N12: 60:00 | O12: hrs | P12: Vishal workload-60:00 | Q12: Non Billable | R12: WL Dec 2026 | S12: B | T12: Vishal PLAdmin | U12: Vishal PLAdmin | V12: Vishal PLAdmin | W12: Vishal PLAdmin | X12: Vishal PLAdmin | Y12: 02/10/2026 10:30 | Z12: 02/10/2026 | AA12: 2.225 | AB12: 20 | AC12: 50.0 | AD12: 200.00 | AE12: false | AF12: https://projects.zoho.com/portal/workload/cv/2?view=all | AG12: https://www.zoho.com/projects/2 | AH12: 9876543202 | AI12: cv2@example.com | AJ12: 2 | AK12: CV multi line 2 second line | AL12: CV single line 2
A13: WL Dec W4 Optimally allocated (1 of 2) - Vishal workload | B13: Vishal workload | C13: To be Tested | E13: wl-optimal | F13: 28/12/2026 | G13: 31/12/2026 | H13: 4 | I13: days | J13: None | K13: 90 | L13: Workload full coverage [Optimally allocated]. Scenario: Optimally allocated week, variant c: total 4.5 h/d + 4:30/d. Expected: Vishal workload: 09:00 h/day on 4 working days (100.00% of 9 h). | M13: 18:00 | N13: 18:00 | O13: hrs | P13: Vishal workload-18:00 | Q13: None | R13: WL Dec 2026 | S13: A,B | T13: vishal PL manager | U13: vishal PL manager | V13: vishal PL manager | W13: Vishal workload,Vishal PLAdmin | X13: Vishal workload,Vishal PLAdmin | Y13: 03/10/2026 11:30 | Z13: 03/10/2026 | AA13: 3.325 | AB13: 30 | AC13: 75.0 | AD13: 300.00 | AE13: true | AF13: https://projects.zoho.com/portal/workload/cv/3?view=all | AG13: https://www.zoho.com/projects/3 | AH13: 9876543203 | AI13: cv3@example.com | AJ13: 3 | AK13: CV multi line 3 second line | AL13: CV single line 3
A14: WL Dec W4 Optimally allocated (2 of 2) - Vishal workload | B14: Vishal workload | C14: On Hold | D14: UIAutomation_Workload_TeamA | E14: wl-optimal | F14: 28/12/2026 | G14: 31/12/2026 | H14: 4 | I14: days | J14: High | K14: 0 | L14: Workload full coverage [Optimally allocated]. Scenario: Optimally allocated week, variant c: total 4.5 h/d + 4:30/d. Expected: Vishal workload: 09:00 h/day on 4 working days (100.00% of 9 h). | M14: 18:00 | N14: 04:30 | O14: hrs/day | P14: Vishal workload-04:30 /day | Q14: Billable | R14: WL Dec 2026
A15: WL Oct W1 Optimally allocated - Vishal PLAdmin | B15: Vishal PLAdmin | C15: Delayed | D15: UIAutomation_Workload_TeamB | E15: wl-optimal | F15: 05/10/2026 | G15: 09/10/2026 | H15: 5 | I15: days | J15: Medium | K15: 10 | L15: Workload full coverage [Optimally allocated]. Scenario: Optimally allocated week, variant b: 100 %/d. Expected: Vishal PLAdmin: 09:00 h/day on 5 working days (100.00% of 9 h). | M15: 45:00 | N15: 100 | O15: %/day | P15: Vishal PLAdmin-100 %/day | Q15: Non Billable | R15: WL Oct 2026 | S15: A | T15: Vishal workload | U15: Vishal workload | V15: Vishal workload | W15: Vishal workload,Vishal PLAdmin | X15: Vishal workload,Vishal PLAdmin | Y15: 01/10/2026 09:30 | Z15: 01/10/2026 | AA15: 1.125 | AB15: 10 | AC15: 25.0 | AD15: 100.00 | AE15: true | AF15: https://projects.zoho.com/portal/workload/cv/1?view=all | AG15: https://www.zoho.com/projects/1 | AH15: 9876543201 | AI15: cv1@example.com | AJ15: 1 | AK15: CV multi line 1 second line | AL15: CV single line 1
A16: WL Oct W2 Under-allocated - Vishal PLAdmin | B16: Vishal PLAdmin | C16: Closed | D16: UIAutomation_Workload_TeamB, UIAutomation_Workload_TeamA | E16: wl-under | F16: 12/10/2026 | G16: 16/10/2026 | H16: 5 | I16: days | J16: Low | K16: 100 | L16: Workload full coverage [Under-allocated]. Scenario: Under-allocated week, variant b: 25 %/d. Expected: Vishal PLAdmin: 02:15 h/day on 5 working days (25.00% of 9 h). | M16: 11:15 | N16: 25 | O16: %/day | P16: Vishal PLAdmin-25 %/day | Q16: None | R16: WL Oct 2026 | S16: B | T16: Vishal PLAdmin | U16: Vishal PLAdmin | V16: Vishal PLAdmin | W16: Vishal PLAdmin | X16: Vishal PLAdmin | Y16: 02/10/2026 10:30 | Z16: 02/10/2026 | AA16: 2.225 | AB16: 20 | AC16: 50.0 | AD16: 200.00 | AE16: false | AF16: https://projects.zoho.com/portal/workload/cv/2?view=all | AG16: https://www.zoho.com/projects/2 | AH16: 9876543202 | AI16: cv2@example.com | AJ16: 2 | AK16: CV multi line 2 second line | AL16: CV single line 2
A17: WL Oct W4 Over-allocated - Vishal PLAdmin | B17: Vishal PLAdmin | C17: Cancelled | E17: wl-over | F17: 26/10/2026 | G17: 30/10/2026 | H17: 5 | I17: days | J17: None | K17: 0 | L17: Workload full coverage [Over-allocated]. Scenario: Over-allocated week, variant b: 150 %/d. Expected: Vishal PLAdmin: 13:30 h/day on 5 working days (150.00% of 9 h). | M17: 67:30 | N17: 150 | O17: %/day | P17: Vishal PLAdmin-150 %/day | Q17: Billable | R17: WL Oct 2026 | S17: A,B | T17: vishal PL manager | U17: vishal PL manager | V17: vishal PL manager | W17: Vishal workload,Vishal PLAdmin | X17: Vishal workload,Vishal PLAdmin | Y17: 03/10/2026 11:30 | Z17: 03/10/2026 | AA17: 3.325 | AB17: 30 | AC17: 75.0 | AD17: 300.00 | AE17: true | AF17: https://projects.zoho.com/portal/workload/cv/3?view=all | AG17: https://www.zoho.com/projects/3 | AH17: 9876543203 | AI17: cv3@example.com | AJ17: 3 | AK17: CV multi line 3 second line | AL17: CV single line 3
A18: WL Nov W1 Under-allocated - Vishal PLAdmin | B18: Vishal PLAdmin | C18: Open | D18: UIAutomation_Workload_TeamA | E18: wl-under | F18: 02/11/2026 | G18: 06/11/2026 | H18: 5 | I18: days | J18: High | K18: 75 | L18: Workload full coverage [Under-allocated]. Scenario: Under-allocated week, variant a: 4:30/d. Expected: Vishal PLAdmin: 04:30 h/day on 5 working days (50.00% of 9 h). | M18: 22:30 | N18: 04:30 | O18: hrs/day | P18: Vishal PLAdmin-04:30 /day | Q18: Non Billable | R18: WL Nov 2026
A19: WL Nov W3 Over-allocated (1 of 2) - Vishal PLAdmin | B19: Vishal PLAdmin | C19: In Progress | D19: UIAutomation_Workload_TeamB | E19: wl-over | F19: 16/11/2026 | G19: 20/11/2026 | H19: 5 | I19: days | J19: Medium | K19: 90 | L19: Workload full coverage [Over-allocated]. Scenario: Over-allocated week, variant a: 6:00/d + 4:30/d. Expected: Vishal PLAdmin: 10:30 h/day on 5 working days (116.67% of 9 h). | M19: 30:00 | N19: 06:00 | O19: hrs/day | P19: Vishal PLAdmin-06:00 /day | Q19: None | R19: WL Nov 2026 | S19: A | T19: Vishal workload | U19: Vishal workload | V19: Vishal workload | W19: Vishal workload,Vishal PLAdmin | X19: Vishal workload,Vishal PLAdmin | Y19: 01/10/2026 09:30 | Z19: 01/10/2026 | AA19: 1.125 | AB19: 10 | AC19: 25.0 | AD19: 100.00 | AE19: true | AF19: https://projects.zoho.com/portal/workload/cv/1?view=all | AG19: https://www.zoho.com/projects/1 | AH19: 9876543201 | AI19: cv1@example.com | AJ19: 1 | AK19: CV multi line 1 second line | AL19: CV single line 1
A20: WL Nov W3 Over-allocated (2 of 2) - Vishal PLAdmin | B20: Vishal PLAdmin | C20: In Review | D20: UIAutomation_Workload_TeamB, UIAutomation_Workload_TeamA | E20: wl-over | F20: 16/11/2026 | G20: 20/11/2026 | H20: 5 | I20: days | J20: Low | K20: 0 | L20: Workload full coverage [Over-allocated]. Scenario: Over-allocated week, variant a: 6:00/d + 4:30/d. Expected: Vishal PLAdmin: 10:30 h/day on 5 working days (116.67% of 9 h). | M20: 22:30 | N20: 04:30 | O20: hrs/day | P20: Vishal PLAdmin-04:30 /day | Q20: Billable | R20: WL Nov 2026 | S20: B | T20: Vishal PLAdmin | U20: Vishal PLAdmin | V20: Vishal PLAdmin | W20: Vishal PLAdmin | X20: Vishal PLAdmin | Y20: 02/10/2026 10:30 | Z20: 02/10/2026 | AA20: 2.225 | AB20: 20 | AC20: 50.0 | AD20: 200.00 | AE20: false | AF20: https://projects.zoho.com/portal/workload/cv/2?view=all | AG20: https://www.zoho.com/projects/2 | AH20: 9876543202 | AI20: cv2@example.com | AJ20: 2 | AK20: CV multi line 2 second line | AL20: CV single line 2
A21: WL Nov W4 Optimally allocated - Vishal PLAdmin | B21: Vishal PLAdmin | C21: To be Tested | E21: wl-optimal | F21: 23/11/2026 | G21: 27/11/2026 | H21: 5 | I21: days | J21: None | K21: 10 | L21: Workload full coverage [Optimally allocated]. Scenario: Optimally allocated week, variant a: 9:00/d. Expected: Vishal PLAdmin: 09:00 h/day on 5 working days (100.00% of 9 h). | M21: 45:00 | N21: 09:00 | O21: hrs/day | P21: Vishal PLAdmin-09:00 /day | Q21: Non Billable | R21: WL Nov 2026 | S21: A,B | T21: vishal PL manager | U21: vishal PL manager | V21: vishal PL manager | W21: Vishal workload,Vishal PLAdmin | X21: Vishal workload,Vishal PLAdmin | Y21: 03/10/2026 11:30 | Z21: 03/10/2026 | AA21: 3.325 | AB21: 30 | AC21: 75.0 | AD21: 300.00 | AE21: true | AF21: https://projects.zoho.com/portal/workload/cv/3?view=all | AG21: https://www.zoho.com/projects/3 | AH21: 9876543203 | AI21: cv3@example.com | AJ21: 3 | AK21: CV multi line 3 second line | AL21: CV single line 3
A22: WL Dec W1 Unallocated - Vishal PLAdmin | B22: Vishal PLAdmin | C22: On Hold | D22: UIAutomation_Workload_TeamA | E22: wl-unallocated | F22: 07/12/2026 | G22: 11/12/2026 | H22: 5 | I22: days | J22: High | K22: 25 | L22: Workload full coverage [Unallocated]. Scenario: Unallocated week, variant d: task with 0:00. Expected: Vishal PLAdmin: 00:00 h/day on 5 working days (0.00% of 9 h). | M22: 00:00 | N22: 00:00 | O22: hrs/day | P22: Vishal PLAdmin-00:00 /day | Q22: None | R22: Workload CV List
A23: WL Dec W2 Over-allocated (1 of 2) - Vishal PLAdmin | B23: Vishal PLAdmin | C23: Delayed | D23: UIAutomation_Workload_TeamB | E23: wl-over | F23: 14/12/2026 | G23: 18/12/2026 | H23: 5 | I23: days | J23: Medium | K23: 50 | L23: Workload full coverage [Over-allocated]. Scenario: Over-allocated week, variant d: 5:00/d + 50 %/d. Expected: Vishal PLAdmin: 09:30 h/day on 5 working days (105.56% of 9 h). | M23: 25:00 | N23: 05:00 | O23: hrs/day | P23: Vishal PLAdmin-05:00 /day | Q23: Billable | R23: WL Dec 2026 | S23: A | T23: Vishal workload | U23: Vishal workload | V23: Vishal workload | W23: Vishal workload,Vishal PLAdmin | X23: Vishal workload,Vishal PLAdmin | Y23: 01/10/2026 09:30 | Z23: 01/10/2026 | AA23: 1.125 | AB23: 10 | AC23: 25.0 | AD23: 100.00 | AE23: true | AF23: https://projects.zoho.com/portal/workload/cv/1?view=all | AG23: https://www.zoho.com/projects/1 | AH23: 9876543201 | AI23: cv1@example.com | AJ23: 1 | AK23: CV multi line 1 second line | AL23: CV single line 1
A24: WL Dec W2 Over-allocated (2 of 2) - Vishal PLAdmin | B24: Vishal PLAdmin | C24: Closed | D24: UIAutomation_Workload_TeamB, UIAutomation_Workload_TeamA | E24: wl-over | F24: 14/12/2026 | G24: 18/12/2026 | H24: 5 | I24: days | J24: Low | K24: 100 | L24: Workload full coverage [Over-allocated]. Scenario: Over-allocated week, variant d: 5:00/d + 50 %/d. Expected: Vishal PLAdmin: 09:30 h/day on 5 working days (105.56% of 9 h). | M24: 22:30 | N24: 50 | O24: %/day | P24: Vishal PLAdmin-50 %/day | Q24: Non Billable | R24: WL Dec 2026 | S24: B | T24: Vishal PLAdmin | U24: Vishal PLAdmin | V24: Vishal PLAdmin | W24: Vishal PLAdmin | X24: Vishal PLAdmin | Y24: 02/10/2026 10:30 | Z24: 02/10/2026 | AA24: 2.225 | AB24: 20 | AC24: 50.0 | AD24: 200.00 | AE24: false | AF24: https://projects.zoho.com/portal/workload/cv/2?view=all | AG24: https://www.zoho.com/projects/2 | AH24: 9876543202 | AI24: cv2@example.com | AJ24: 2 | AK24: CV multi line 2 second line | AL24: CV single line 2
A25: WL Dec W3 Optimally allocated - Vishal PLAdmin | B25: Vishal PLAdmin | C25: Cancelled | E25: wl-optimal | F25: 21/12/2026 | G25: 25/12/2026 | H25: 5 | I25: days | J25: None | K25: 0 | L25: Workload full coverage [Optimally allocated]. Scenario: Optimally allocated week, variant d: total 9 h/d. Expected: Vishal PLAdmin: 09:00 h/day on 5 working days (100.00% of 9 h). | M25: 45:00 | N25: 45:00 | O25: hrs | P25: Vishal PLAdmin-45:00 | Q25: None | R25: WL Dec 2026 | S25: A,B | T25: vishal PL manager | U25: vishal PL manager | V25: vishal PL manager | W25: Vishal workload,Vishal PLAdmin | X25: Vishal workload,Vishal PLAdmin | Y25: 03/10/2026 11:30 | Z25: 03/10/2026 | AA25: 3.325 | AB25: 30 | AC25: 75.0 | AD25: 300.00 | AE25: true | AF25: https://projects.zoho.com/portal/workload/cv/3?view=all | AG25: https://www.zoho.com/projects/3 | AH25: 9876543203 | AI25: cv3@example.com | AJ25: 3 | AK25: CV multi line 3 second line | AL25: CV single line 3
A26: WL Dec W4 Under-allocated - Vishal PLAdmin | B26: Vishal PLAdmin | C26: Open | D26: UIAutomation_Workload_TeamA | E26: wl-under | F26: 28/12/2026 | G26: 31/12/2026 | H26: 4 | I26: days | J26: High | K26: 0 | L26: Workload full coverage [Under-allocated]. Scenario: Under-allocated week, variant d: 8:30/d. Expected: Vishal PLAdmin: 08:30 h/day on 4 working days (94.44% of 9 h). | M26: 34:00 | N26: 08:30 | O26: hrs/day | P26: Vishal PLAdmin-08:30 /day | Q26: Billable | R26: WL Dec 2026
A27: WL Oct W1 Under-allocated - vishal PL manager | B27: vishal PL manager | C27: In Progress | D27: UIAutomation_Workload_TeamB | E27: wl-under | F27: 05/10/2026 | G27: 09/10/2026 | H27: 5 | I27: days | J27: Medium | K27: 10 | L27: Workload full coverage [Under-allocated]. Scenario: Under-allocated week, variant c: total 3 h/d. Expected: vishal PL manager: 03:00 h/day on 5 working days (33.33% of 9 h). | M27: 15:00 | N27: 15:00 | O27: hrs | P27: vishal PL manager-15:00 | Q27: Non Billable | R27: WL Oct 2026 | S27: A | T27: Vishal workload | U27: Vishal workload | V27: Vishal workload | W27: Vishal workload,Vishal PLAdmin | X27: Vishal workload,Vishal PLAdmin | Y27: 01/10/2026 09:30 | Z27: 01/10/2026 | AA27: 1.125 | AB27: 10 | AC27: 25.0 | AD27: 100.00 | AE27: true | AF27: https://projects.zoho.com/portal/workload/cv/1?view=all | AG27: https://www.zoho.com/projects/1 | AH27: 9876543201 | AI27: cv1@example.com | AJ27: 1 | AK27: CV multi line 1 second line | AL27: CV single line 1
A28: WL Oct W3 Over-allocated - vishal PL manager | B28: vishal PL manager | C28: In Review | D28: UIAutomation_Workload_TeamB, UIAutomation_Workload_TeamA | E28: wl-over | F28: 19/10/2026 | G28: 23/10/2026 | H28: 5 | I28: days | J28: Low | K28: 25 | L28: Workload full coverage [Over-allocated]. Scenario: Over-allocated week, variant c: total 12 h/d. Expected: vishal PL manager: 12:00 h/day on 5 working days (133.33% of 9 h). | M28: 60:00 | N28: 60:00 | O28: hrs | P28: vishal PL manager-60:00 | Q28: None | R28: WL Oct 2026 | S28: B | T28: Vishal PLAdmin | U28: Vishal PLAdmin | V28: Vishal PLAdmin | W28: Vishal PLAdmin | X28: Vishal PLAdmin | Y28: 02/10/2026 10:30 | Z28: 02/10/2026 | AA28: 2.225 | AB28: 20 | AC28: 50.0 | AD28: 200.00 | AE28: false | AF28: https://projects.zoho.com/portal/workload/cv/2?view=all | AG28: https://www.zoho.com/projects/2 | AH28: 9876543202 | AI28: cv2@example.com | AJ28: 2 | AK28: CV multi line 2 second line | AL28: CV single line 2
A29: WL Oct W4 Optimally allocated (1 of 2) - vishal PL manager | B29: vishal PL manager | C29: To be Tested | E29: wl-optimal | F29: 26/10/2026 | G29: 30/10/2026 | H29: 5 | I29: days | J29: None | K29: 50 | L29: Workload full coverage [Optimally allocated]. Scenario: Optimally allocated week, variant c: total 4.5 h/d + 4:30/d. Expected: vishal PL manager: 09:00 h/day on 5 working days (100.00% of 9 h). | M29: 22:30 | N29: 22:30 | O29: hrs | P29: vishal PL manager-22:30 | Q29: Billable | R29: WL Oct 2026 | S29: A,B | T29: vishal PL manager | U29: vishal PL manager | V29: vishal PL manager | W29: Vishal workload,Vishal PLAdmin | X29: Vishal workload,Vishal PLAdmin | Y29: 03/10/2026 11:30 | Z29: 03/10/2026 | AA29: 3.325 | AB29: 30 | AC29: 75.0 | AD29: 300.00 | AE29: true | AF29: https://projects.zoho.com/portal/workload/cv/3?view=all | AG29: https://www.zoho.com/projects/3 | AH29: 9876543203 | AI29: cv3@example.com | AJ29: 3 | AK29: CV multi line 3 second line | AL29: CV single line 3
A30: WL Oct W4 Optimally allocated (2 of 2) - vishal PL manager | B30: vishal PL manager | C30: On Hold | D30: UIAutomation_Workload_TeamA | E30: wl-optimal | F30: 26/10/2026 | G30: 30/10/2026 | H30: 5 | I30: days | J30: High | K30: 75 | L30: Workload full coverage [Optimally allocated]. Scenario: Optimally allocated week, variant c: total 4.5 h/d + 4:30/d. Expected: vishal PL manager: 09:00 h/day on 5 working days (100.00% of 9 h). | M30: 22:30 | N30: 04:30 | O30: hrs/day | P30: vishal PL manager-04:30 /day | Q30: Non Billable | R30: WL Oct 2026
A31: WL Nov W2 Over-allocated - vishal PL manager | B31: vishal PL manager | C31: Delayed | D31: UIAutomation_Workload_TeamB | E31: wl-over | F31: 09/11/2026 | G31: 13/11/2026 | H31: 5 | I31: days | J31: Medium | K31: 90 | L31: Workload full coverage [Over-allocated]. Scenario: Over-allocated week, variant b: 150 %/d. Expected: vishal PL manager: 13:30 h/day on 5 working days (150.00% of 9 h). | M31: 67:30 | N31: 150 | O31: %/day | P31: vishal PL manager-150 %/day | Q31: None | R31: WL Nov 2026 | S31: A | T31: Vishal workload | U31: Vishal workload | V31: Vishal workload | W31: Vishal workload,Vishal PLAdmin | X31: Vishal workload,Vishal PLAdmin | Y31: 01/10/2026 09:30 | Z31: 01/10/2026 | AA31: 1.125 | AB31: 10 | AC31: 25.0 | AD31: 100.00 | AE31: true | AF31: https://projects.zoho.com/portal/workload/cv/1?view=all | AG31: https://www.zoho.com/projects/1 | AH31: 9876543201 | AI31: cv1@example.com | AJ31: 1 | AK31: CV multi line 1 second line | AL31: CV single line 1
A32: WL Nov W3 Optimally allocated - vishal PL manager | B32: vishal PL manager | C32: Closed | D32: UIAutomation_Workload_TeamB, UIAutomation_Workload_TeamA | E32: wl-optimal | F32: 16/11/2026 | G32: 20/11/2026 | H32: 5 | I32: days | J32: Low | K32: 100 | L32: Workload full coverage [Optimally allocated]. Scenario: Optimally allocated week, variant b: 100 %/d. Expected: vishal PL manager: 09:00 h/day on 5 working days (100.00% of 9 h). | M32: 45:00 | N32: 100 | O32: %/day | P32: vishal PL manager-100 %/day | Q32: Billable | R32: WL Nov 2026 | S32: B | T32: Vishal PLAdmin | U32: Vishal PLAdmin | V32: Vishal PLAdmin | W32: Vishal PLAdmin | X32: Vishal PLAdmin | Y32: 02/10/2026 10:30 | Z32: 02/10/2026 | AA32: 2.225 | AB32: 20 | AC32: 50.0 | AD32: 200.00 | AE32: false | AF32: https://projects.zoho.com/portal/workload/cv/2?view=all | AG32: https://www.zoho.com/projects/2 | AH32: 9876543202 | AI32: cv2@example.com | AJ32: 2 | AK32: CV multi line 2 second line | AL32: CV single line 2
A33: WL Nov W4 Under-allocated - vishal PL manager | B33: vishal PL manager | C33: Cancelled | E33: wl-under | F33: 23/11/2026 | G33: 27/11/2026 | H33: 5 | I33: days | J33: None | K33: 0 | L33: Workload full coverage [Under-allocated]. Scenario: Under-allocated week, variant b: 25 %/d. Expected: vishal PL manager: 02:15 h/day on 5 working days (25.00% of 9 h). | M33: 11:15 | N33: 25 | O33: %/day | P33: vishal PL manager-25 %/day | Q33: Non Billable | R33: WL Nov 2026 | S33: A,B | T33: vishal PL manager | U33: vishal PL manager | V33: vishal PL manager | W33: Vishal workload,Vishal PLAdmin | X33: Vishal workload,Vishal PLAdmin | Y33: 03/10/2026 11:30 | Z33: 03/10/2026 | AA33: 3.325 | AB33: 30 | AC33: 75.0 | AD33: 300.00 | AE33: true | AF33: https://projects.zoho.com/portal/workload/cv/3?view=all | AG33: https://www.zoho.com/projects/3 | AH33: 9876543203 | AI33: cv3@example.com | AJ33: 3 | AK33: CV multi line 3 second line | AL33: CV single line 3
A34: WL Dec W1 Over-allocated (1 of 2) - vishal PL manager | B34: vishal PL manager | C34: Open | D34: UIAutomation_Workload_TeamA | E34: wl-over | F34: 07/12/2026 | G34: 11/12/2026 | H34: 5 | I34: days | J34: High | K34: 25 | L34: Workload full coverage [Over-allocated]. Scenario: Over-allocated week, variant a: 6:00/d + 4:30/d. Expected: vishal PL manager: 10:30 h/day on 5 working days (116.67% of 9 h). | M34: 30:00 | N34: 06:00 | O34: hrs/day | P34: vishal PL manager-06:00 /day | Q34: None | R34: WL Dec 2026
A35: WL Dec W1 Over-allocated (2 of 2) - vishal PL manager | B35: vishal PL manager | C35: In Progress | D35: UIAutomation_Workload_TeamB | E35: wl-over | F35: 07/12/2026 | G35: 11/12/2026 | H35: 5 | I35: days | J35: Medium | K35: 50 | L35: Workload full coverage [Over-allocated]. Scenario: Over-allocated week, variant a: 6:00/d + 4:30/d. Expected: vishal PL manager: 10:30 h/day on 5 working days (116.67% of 9 h). | M35: 22:30 | N35: 04:30 | O35: hrs/day | P35: vishal PL manager-04:30 /day | Q35: Billable | R35: WL Dec 2026 | S35: A | T35: Vishal workload | U35: Vishal workload | V35: Vishal workload | W35: Vishal workload,Vishal PLAdmin | X35: Vishal workload,Vishal PLAdmin | Y35: 01/10/2026 09:30 | Z35: 01/10/2026 | AA35: 1.125 | AB35: 10 | AC35: 25.0 | AD35: 100.00 | AE35: true | AF35: https://projects.zoho.com/portal/workload/cv/1?view=all | AG35: https://www.zoho.com/projects/1 | AH35: 9876543201 | AI35: cv1@example.com | AJ35: 1 | AK35: CV multi line 1 second line | AL35: CV single line 1
A36: WL Dec W2 Optimally allocated - vishal PL manager | B36: vishal PL manager | C36: In Review | D36: UIAutomation_Workload_TeamB, UIAutomation_Workload_TeamA | E36: wl-optimal | F36: 14/12/2026 | G36: 18/12/2026 | H36: 5 | I36: days | J36: Low | K36: 75 | L36: Workload full coverage [Optimally allocated]. Scenario: Optimally allocated week, variant a: 9:00/d. Expected: vishal PL manager: 09:00 h/day on 5 working days (100.00% of 9 h). | M36: 45:00 | N36: 09:00 | O36: hrs/day | P36: vishal PL manager-09:00 /day | Q36: Non Billable | R36: WL Dec 2026 | S36: B | T36: Vishal PLAdmin | U36: Vishal PLAdmin | V36: Vishal PLAdmin | W36: Vishal PLAdmin | X36: Vishal PLAdmin | Y36: 02/10/2026 10:30 | Z36: 02/10/2026 | AA36: 2.225 | AB36: 20 | AC36: 50.0 | AD36: 200.00 | AE36: false | AF36: https://projects.zoho.com/portal/workload/cv/2?view=all | AG36: https://www.zoho.com/projects/2 | AH36: 9876543202 | AI36: cv2@example.com | AJ36: 2 | AK36: CV multi line 2 second line | AL36: CV single line 2
A37: WL Dec W3 Under-allocated - vishal PL manager | B37: vishal PL manager | C37: To be Tested | E37: wl-under | F37: 21/12/2026 | G37: 25/12/2026 | H37: 5 | I37: days | J37: None | K37: 90 | L37: Workload full coverage [Under-allocated]. Scenario: Under-allocated week, variant a: 4:30/d. Expected: vishal PL manager: 04:30 h/day on 5 working days (50.00% of 9 h). | M37: 22:30 | N37: 04:30 | O37: hrs/day | P37: vishal PL manager-04:30 /day | Q37: None | R37: WL Dec 2026 | S37: A,B | T37: vishal PL manager | U37: vishal PL manager | V37: vishal PL manager | W37: Vishal workload,Vishal PLAdmin | X37: Vishal workload,Vishal PLAdmin | Y37: 03/10/2026 11:30 | Z37: 03/10/2026 | AA37: 3.325 | AB37: 30 | AC37: 75.0 | AD37: 300.00 | AE37: true | AF37: https://projects.zoho.com/portal/workload/cv/3?view=all | AG37: https://www.zoho.com/projects/3 | AH37: 9876543203 | AI37: cv3@example.com | AJ37: 3 | AK37: CV multi line 3 second line | AL37: CV single line 3
A38: WL Oct W1 Unallocated - Vishal plemployee | B38: Vishal plemployee | C38: On Hold | D38: UIAutomation_Workload_TeamA | E38: wl-unallocated | F38: 05/10/2026 | G38: 09/10/2026 | H38: 5 | I38: days | J38: High | K38: 0 | L38: Workload full coverage [Unallocated]. Scenario: Unallocated week, variant d: task with 0:00. Expected: Vishal plemployee: 00:00 h/day on 5 working days (0.00% of 9 h). | M38: 00:00 | N38: 00:00 | O38: hrs/day | P38: Vishal plemployee-00:00 /day | Q38: Billable | R38: Workload CV List
A39: WL Oct W2 Over-allocated (1 of 2) - Vishal plemployee | B39: Vishal plemployee | C39: Delayed | D39: UIAutomation_Workload_TeamB | E39: wl-over | F39: 12/10/2026 | G39: 16/10/2026 | H39: 5 | I39: days | J39: Medium | K39: 10 | L39: Workload full coverage [Over-allocated]. Scenario: Over-allocated week, variant d: 5:00/d + 50 %/d. Expected: Vishal plemployee: 09:30 h/day on 5 working days (105.56% of 9 h). | M39: 25:00 | N39: 05:00 | O39: hrs/day | P39: Vishal plemployee-05:00 /day | Q39: Non Billable | R39: WL Oct 2026 | S39: A | T39: Vishal workload | U39: Vishal workload | V39: Vishal workload | W39: Vishal workload,Vishal PLAdmin | X39: Vishal workload,Vishal PLAdmin | Y39: 01/10/2026 09:30 | Z39: 01/10/2026 | AA39: 1.125 | AB39: 10 | AC39: 25.0 | AD39: 100.00 | AE39: true | AF39: https://projects.zoho.com/portal/workload/cv/1?view=all | AG39: https://www.zoho.com/projects/1 | AH39: 9876543201 | AI39: cv1@example.com | AJ39: 1 | AK39: CV multi line 1 second line | AL39: CV single line 1
A40: WL Oct W2 Over-allocated (2 of 2) - Vishal plemployee | B40: Vishal plemployee | C40: Closed | D40: UIAutomation_Workload_TeamB, UIAutomation_Workload_TeamA | E40: wl-over | F40: 12/10/2026 | G40: 16/10/2026 | H40: 5 | I40: days | J40: Low | K40: 100 | L40: Workload full coverage [Over-allocated]. Scenario: Over-allocated week, variant d: 5:00/d + 50 %/d. Expected: Vishal plemployee: 09:30 h/day on 5 working days (105.56% of 9 h). | M40: 22:30 | N40: 50 | O40: %/day | P40: Vishal plemployee-50 %/day | Q40: None | R40: WL Oct 2026 | S40: B | T40: Vishal PLAdmin | U40: Vishal PLAdmin | V40: Vishal PLAdmin | W40: Vishal PLAdmin | X40: Vishal PLAdmin | Y40: 02/10/2026 10:30 | Z40: 02/10/2026 | AA40: 2.225 | AB40: 20 | AC40: 50.0 | AD40: 200.00 | AE40: false | AF40: https://projects.zoho.com/portal/workload/cv/2?view=all | AG40: https://www.zoho.com/projects/2 | AH40: 9876543202 | AI40: cv2@example.com | AJ40: 2 | AK40: CV multi line 2 second line | AL40: CV single line 2
...

Sheet Verification 08-10-2026
A1: Workload Report vs expected - observed 08-10-2026 (All Users, Allocated Man Days, month periods)
A2: Expected = Monthly Expected (this project, previous import included). Report also contains other projects and UI1-T1, explained in the last column.
A4: Month | B4: User | C4: Report (man-days) | D4: Report (hrs) | E4: Expected (hrs) | F4: Delta (hrs) | G4: Result | H4: Explanation
A5: Oct 2026 | B5: Unassigned | C5: 2.222 | D5: =C5*'Assignment Calc'!$B$1 -> 19.998 | E5: =SUMPRODUCT(('Monthly Expected'!$A$2:$A$100=B5)*('Monthly Expected'!$B$2:$B$100=A5)*'Monthly Expected'!$F$2:$F$100) -> 20 | F5: =ROUND(D5-E5,1) -> 0 | G5: =IF(ABS(F5)<0.2,"Match",IF(ISNUMBER(SEARCH("FINDING",H5)),"Explained - finding","Explained - other data")) -> Match
A6: Oct 2026 | B6: UIAutomation_Workload_Resource | C6: 15.6 | D6: =C6*'Assignment Calc'!$B$1 -> 140.4 | E6: =SUMPRODUCT(('Monthly Expected'!$A$2:$A$100=B6)*('Monthly Expected'!$B$2:$B$100=A6)*'Monthly Expected'!$F$2:$F$100) -> 140.4 | F6: =ROUND(D6-E6,1) -> 0 | G6: =IF(ABS(F6)<0.2,"Match",IF(ISNUMBER(SEARCH("FINDING",H6)),"Explained - finding","Explained - other data")) -> Match
A7: Oct 2026 | B7: Vishal customprofile | C7: 15.333 | D7: =C7*'Assignment Calc'!$B$1 -> 137.997 | E7: =SUMPRODUCT(('Monthly Expected'!$A$2:$A$100=B7)*('Monthly Expected'!$B$2:$B$100=A7)*'Monthly Expected'!$F$2:$F$100) -> 147 | F7: =ROUND(D7-E7,1) -> -9 | G7: =IF(ABS(F7)<0.2,"Match",IF(ISNUMBER(SEARCH("FINDING",H7)),"Explained - finding","Explained - other data")) -> Explained - finding | H7: -9 h FINDING F1 (WL-E05 150 %/day stored as 18:00 = 100 %).
A8: Oct 2026 | B8: Vishal liteuser | C8: 12.25 | D8: =C8*'Assignment Calc'!$B$1 -> 110.25 | E8: =SUMPRODUCT(('Monthly Expected'!$A$2:$A$100=B8)*('Monthly Expected'!$B$2:$B$100=A8)*'Monthly Expected'!$F$2:$F$100) -> 132.75 | F8: =ROUND(D8-E8,1) -> -22.5 | G8: =IF(ABS(F8)<0.2,"Match",IF(ISNUMBER(SEARCH("FINDING",H8)),"Explained - finding","Explained - other data")) -> Explained - finding | H8: -22.5 h FINDING F1 (150 %/day capped to 100 %, Oct over week).
A9: Oct 2026 | B9: vishal PL manager | C9: 38.667 | D9: =C9*'Assignment Calc'!$B$1 -> 348.003 | E9: =SUMPRODUCT(('Monthly Expected'!$A$2:$A$100=B9)*('Monthly Expected'!$B$2:$B$100=A9)*'Monthly Expected'!$F$2:$F$100) -> 219 | F9: =ROUND(D9-E9,1) -> 129 | G9: =IF(ABS(F9)<0.2,"Match",IF(ISNUMBER(SEARCH("FINDING",H9)),"Explained - finding","Explained - other data")) -> Explained - finding | H9: +121 h UI1-T1 / other projects (pre-import 220 h - previous import 99 h); +8 h FINDING F2 (WL-E03 weekend-only task allocates 4 h on Sat 3 + Sun 4 Oct).
A10: Oct 2026 | B10: Vishal PLAdmin | C10: 56.583 | D10: =C10*'Assignment Calc'!$B$1 -> 509.247 | E10: =SUMPRODUCT(('Monthly Expected'!$A$2:$A$100=B10)*('Monthly Expected'!$B$2:$B$100=A10)*'Monthly Expected'!$F$2:$F$100) -> 333.75 | F10: =ROUND(D10-E10,1) -> 175.5 | G10: =IF(ABS(F10)<0.2,"Match",IF(ISNUMBER(SEARCH("FINDING",H10)),"Explained - finding","Explained - other data")) -> Explained - finding | H10: +198 h other projects (pre-import 396 h - previous import 198 h); -22.5 h FINDING F1 (150 %/day capped to 100 %, Oct W2).
A11: Oct 2026 | B11: Vishal plemployee | C11: 15 | D11: =C11*'Assignment Calc'!$B$1 -> 135 | E11: =SUMPRODUCT(('Monthly Expected'!$A$2:$A$100=B11)*('Monthly Expected'!$B$2:$B$100=A11)*'Monthly Expected'!$F$2:$F$100) -> 135 | F11: =ROUND(D11-E11,1) -> 0 | G11: =IF(ABS(F11)<0.2,"Match",IF(ISNUMBER(SEARCH("FINDING",H11)),"Explained - finding","Explained - other data")) -> Match
A12: Oct 2026 | B12: Vishal plreadonly | C12: 13.333 | D12: =C12*'Assignment Calc'!$B$1 -> 119.997 | E12: =SUMPRODUCT(('Monthly Expected'!$A$2:$A$100=B12)*('Monthly Expected'!$B$2:$B$100=A12)*'Monthly Expected'!$F$2:$F$100) -> 120 | F12: =ROUND(D12-E12,1) -> 0 | G12: =IF(ABS(F12)<0.2,"Match",IF(ISNUMBER(SEARCH("FINDING",H12)),"Explained - finding","Explained - other data")) -> Match
A13: Oct 2026 | B13: Vishal workload | C13: 131.333 | D13: =C13*'Assignment Calc'!$B$1 -> 1181.997 | E13: =SUMPRODUCT(('Monthly Expected'!$A$2:$A$100=B13)*('Monthly Expected'!$B$2:$B$100=A13)*'Monthly Expected'!$F$2:$F$100) -> 633 | F13: =ROUND(D13-E13,1) -> 549 | G13: =IF(ABS(F13)<0.2,"Match",IF(ISNUMBER(SEARCH("FINDING",H13)),"Explained - finding","Explained - other data")) -> Explained - other data | H13: Other projects (NI-6, NI-1) = +549 h (pre-import total 1044 h - previous import 495 h).
A14: Nov 2026 | B14: Unassigned | C14: 0 | D14: =C14*'Assignment Calc'!$B$1 -> 0 | E14: =SUMPRODUCT(('Monthly Expected'!$A$2:$A$100=B14)*('Monthly Expected'!$B$2:$B$100=A14)*'Monthly Expected'!$F$2:$F$100) -> 0 | F14: =ROUND(D14-E14,1) -> 0 | G14: =IF(ABS(F14)<0.2,"Match",IF(ISNUMBER(SEARCH("FINDING",H14)),"Explained - finding","Explained - other data")) -> Match
A15: Nov 2026 | B15: UIAutomation_Workload_Resource | C15: 14.333 | D15: =C15*'Assignment Calc'!$B$1 -> 128.997 | E15: =SUMPRODUCT(('Monthly Expected'!$A$2:$A$100=B15)*('Monthly Expected'!$B$2:$B$100=A15)*'Monthly Expected'!$F$2:$F$100) -> 129 | F15: =ROUND(D15-E15,1) -> 0 | G15: =IF(ABS(F15)<0.2,"Match",IF(ISNUMBER(SEARCH("FINDING",H15)),"Explained - finding","Explained - other data")) -> Match
A16: Nov 2026 | B16: Vishal customprofile | C16: 11.25 | D16: =C16*'Assignment Calc'!$B$1 -> 101.25 | E16: =SUMPRODUCT(('Monthly Expected'!$A$2:$A$100=B16)*('Monthly Expected'!$B$2:$B$100=A16)*'Monthly Expected'!$F$2:$F$100) -> 123.75 | F16: =ROUND(D16-E16,1) -> -22.5 | G16: =IF(ABS(F16)<0.2,"Match",IF(ISNUMBER(SEARCH("FINDING",H16)),"Explained - finding","Explained - other data")) -> Explained - finding | H16: -22.5 h FINDING F1 (150 %/day capped, Nov over week).
A17: Nov 2026 | B17: Vishal liteuser | C17: 13.333 | D17: =C17*'Assignment Calc'!$B$1 -> 119.997 | E17: =SUMPRODUCT(('Monthly Expected'!$A$2:$A$100=B17)*('Monthly Expected'!$B$2:$B$100=A17)*'Monthly Expected'!$F$2:$F$100) -> 120 | F17: =ROUND(D17-E17,1) -> 0 | G17: =IF(ABS(F17)<0.2,"Match",IF(ISNUMBER(SEARCH("FINDING",H17)),"Explained - finding","Explained - other data")) -> Match
A18: Nov 2026 | B18: vishal PL manager | C18: 11.75 | D18: =C18*'Assignment Calc'!$B$1 -> 105.75 | E18: =SUMPRODUCT(('Monthly Expected'!$A$2:$A$100=B18)*('Monthly Expected'!$B$2:$B$100=A18)*'Monthly Expected'!$F$2:$F$100) -> 128.25 | F18: =ROUND(D18-E18,1) -> -22.5 | G18: =IF(ABS(F18)<0.2,"Match",IF(ISNUMBER(SEARCH("FINDING",H18)),"Explained - finding","Explained - other data")) -> Explained - finding | H18: -22.5 h FINDING F1 (150 %/day capped, Nov over week).
A19: Nov 2026 | B19: Vishal PLAdmin | C19: 13.333 | D19: =C19*'Assignment Calc'!$B$1 -> 119.997 | E19: =SUMPRODUCT(('Monthly Expected'!$A$2:$A$100=B19)*('Monthly Expected'!$B$2:$B$100=A19)*'Monthly Expected'!$F$2:$F$100) -> 120 | F19: =ROUND(D19-E19,1) -> 0 | G19: =IF(ABS(F19)<0.2,"Match",IF(ISNUMBER(SEARCH("FINDING",H19)),"Explained - finding","Explained - other data")) -> Match
A20: Nov 2026 | B20: Vishal plemployee | C20: 23.833 | D20: =C20*'Assignment Calc'!$B$1 -> 214.497 | E20: =SUMPRODUCT(('Monthly Expected'!$A$2:$A$100=B20)*('Monthly Expected'!$B$2:$B$100=A20)*'Monthly Expected'!$F$2:$F$100) -> 169.5 | F20: =ROUND(D20-E20,1) -> 45 | G20: =IF(ABS(F20)<0.2,"Match",IF(ISNUMBER(SEARCH("FINDING",H20)),"Explained - finding","Explained - other data")) -> Explained - other data | H20: +45 h: two NI-6 tasks at 4:30/day on 2-6 Nov (expanded row, verified).
A21: Nov 2026 | B21: Vishal plreadonly | C21: 16 | D21: =C21*'Assignment Calc'!$B$1 -> 144 | E21: =SUMPRODUCT(('Monthly Expected'!$A$2:$A$100=B21)*('Monthly Expected'!$B$2:$B$100=A21)*'Monthly Expected'!$F$2:$F$100) -> 144 | F21: =ROUND(D21-E21,1) -> 0 | G21: =IF(ABS(F21)<0.2,"Match",IF(ISNUMBER(SEARCH("FINDING",H21)),"Explained - finding","Explained - other data")) -> Match
A22: Nov 2026 | B22: Vishal workload | C22: 20 | D22: =C22*'Assignment Calc'!$B$1 -> 180 | E22: =SUMPRODUCT(('Monthly Expected'!$A$2:$A$100=B22)*('Monthly Expected'!$B$2:$B$100=A22)*'Monthly Expected'!$F$2:$F$100) -> 157.5 | F22: =ROUND(D22-E22,1) -> 22.5 | G22: =IF(ABS(F22)<0.2,"Match",IF(ISNUMBER(SEARCH("FINDING",H22)),"Explained - finding","Explained - other data")) -> Explained - other data | H22: +22.5 h: other project tasks (not expanded - verify).
A23: Dec 2026 | B23: Unassigned | C23: 0 | D23: =C23*'Assignment Calc'!$B$1 -> 0 | E23: =SUMPRODUCT(('Monthly Expected'!$A$2:$A$100=B23)*('Monthly Expected'!$B$2:$B$100=A23)*'Monthly Expected'!$F$2:$F$100) -> 0 | F23: =ROUND(D23-E23,1) -> 0 | G23: =IF(ABS(F23)<0.2,"Match",IF(ISNUMBER(SEARCH("FINDING",H23)),"Explained - finding","Explained - other data")) -> Match
A24: Dec 2026 | B24: UIAutomation_Workload_Resource | C24: 14.25 | D24: =C24*'Assignment Calc'!$B$1 -> 128.25 | E24: =SUMPRODUCT(('Monthly Expected'!$A$2:$A$100=B24)*('Monthly Expected'!$B$2:$B$100=A24)*'Monthly Expected'!$F$2:$F$100) -> 146.25 | F24: =ROUND(D24-E24,1) -> -18 | G24: =IF(ABS(F24)<0.2,"Match",IF(ISNUMBER(SEARCH("FINDING",H24)),"Explained - finding","Explained - other data")) -> Explained - finding | H24: -18 h FINDING F1 (150 %/day capped, Dec 28-31 over week, 4 days).
A25: Dec 2026 | B25: Vishal customprofile | C25: 14.667 | D25: =C25*'Assignment Calc'!$B$1 -> 132.003 | E25: =SUMPRODUCT(('Monthly Expected'!$A$2:$A$100=B25)*('Monthly Expected'!$B$2:$B$100=A25)*'Monthly Expected'!$F$2:$F$100) -> 132 | F25: =ROUND(D25-E25,1) -> 0 | G25: =IF(ABS(F25)<0.2,"Match",IF(ISNUMBER(SEARCH("FINDING",H25)),"Explained - finding","Explained - other data")) -> Match
A26: Dec 2026 | B26: Vishal liteuser | C26: 16.722 | D26: =C26*'Assignment Calc'!$B$1 -> 150.498 | E26: =SUMPRODUCT(('Monthly Expected'!$A$2:$A$100=B26)*('Monthly Expected'!$B$2:$B$100=A26)*'Monthly Expected'!$F$2:$F$100) -> 150.5 | F26: =ROUND(D26-E26,1) -> 0 | G26: =IF(ABS(F26)<0.2,"Match",IF(ISNUMBER(SEARCH("FINDING",H26)),"Explained - finding","Explained - other data")) -> Match
A27: Dec 2026 | B27: vishal PL manager | C27: 19.333 | D27: =C27*'Assignment Calc'!$B$1 -> 173.997 | E27: =SUMPRODUCT(('Monthly Expected'!$A$2:$A$100=B27)*('Monthly Expected'!$B$2:$B$100=A27)*'Monthly Expected'!$F$2:$F$100) -> 151.5 | F27: =ROUND(D27-E27,1) -> 22.5 | G27: =IF(ABS(F27)<0.2,"Match",IF(ISNUMBER(SEARCH("FINDING",H27)),"Explained - finding","Explained - other data")) -> Explained - other data | H27: +22.5 h: NI-6 task 4:30/day on 7-11 Dec (expanded row, verified).
A28: Dec 2026 | B28: Vishal PLAdmin | C28: 15.056 | D28: =C28*'Assignment Calc'!$B$1 -> 135.504 | E28: =SUMPRODUCT(('Monthly Expected'!$A$2:$A$100=B28)*('Monthly Expected'!$B$2:$B$100=A28)*'Monthly Expected'!$F$2:$F$100) -> 135.5 | F28: =ROUND(D28-E28,1) -> 0 | G28: =IF(ABS(F28)<0.2,"Match",IF(ISNUMBER(SEARCH("FINDING",H28)),"Explained - finding","Explained - other data")) -> Match
A29: Dec 2026 | B29: Vishal plemployee | C29: 10.25 | D29: =C29*'Assignment Calc'!$B$1 -> 92.25 | E29: =SUMPRODUCT(('Monthly Expected'!$A$2:$A$100=B29)*('Monthly Expected'!$B$2:$B$100=A29)*'Monthly Expected'!$F$2:$F$100) -> 110.25 | F29: =ROUND(D29-E29,1) -> -18 | G29: =IF(ABS(F29)<0.2,"Match",IF(ISNUMBER(SEARCH("FINDING",H29)),"Explained - finding","Explained - other data")) -> Explained - finding | H29: -18 h FINDING F1 (150 %/day capped, Dec 28-31 over week, 4 days).
A30: Dec 2026 | B30: Vishal plreadonly | C30: 16.333 | D30: =C30*'Assignment Calc'!$B$1 -> 146.997 | E30: =SUMPRODUCT(('Monthly Expected'!$A$2:$A$100=B30)*('Monthly Expected'!$B$2:$B$100=A30)*'Monthly Expected'!$F$2:$F$100) -> 147 | F30: =ROUND(D30-E30,1) -> 0 | G30: =IF(ABS(F30)<0.2,"Match",IF(ISNUMBER(SEARCH("FINDING",H30)),"Explained - finding","Explained - other data")) -> Match
A31: Dec 2026 | B31: Vishal workload | C31: 14.333 | D31: =C31*'Assignment Calc'!$B$1 -> 128.997 | E31: =SUMPRODUCT(('Monthly Expected'!$A$2:$A$100=B31)*('Monthly Expected'!$B$2:$B$100=A31)*'Monthly Expected'!$F$2:$F$100) -> 129 | F31: =ROUND(D31-E31,1) -> 0 | G31: =IF(ABS(F31)<0.2,"Match",IF(ISNUMBER(SEARCH("FINDING",H31)),"Explained - finding","Explained - other data")) -> Match
A33: FINDINGS
A34: F1 | B34: Import caps Work %/day at 100 %. WL-E05 (150 %/day, 2 days) was stored as Work Hours 18:00 instead of 27:00; every 150 %/day row lost 4.5 h/day. No warning in the import wizard.
A35: F2 | B35: A task whose whole range is non-working days (WL-E03, Sat 3 - Sun 4 Oct, 4:00 hrs/day) is allocated 4 h on Saturday and Sunday (0.444d each) although business hours are Mon-Fri.
A36: F3 | B36: Associated Team and Tags columns did not import (checked UI1-T114 and UI1-T15: both empty; file had UIAutomation_Workload_TeamA/B and wl-edge / wl-over). Custom fields, priority, billing, % completed, dates and work hours did import.
A37: F4 | B37: Import creates a new task list even when one with the same name exists (second "Workload CV List" and second "General").
A38: F5 | B38: Importer reads rows from EVERY sheet of the workbook (Scenario Matrix text appeared as statuses) - keep the import file to a single Tasks sheet.
A39: OK | B39: Unassigned task with hours (WL-E10) shows 4:00/day under Unassigned User; resource, read-only and lite users can own tasks; multi-owner hrs and % split correctly (WL-E08, WL-E09); cross-month and weekend-span totals split correctly (WL-E06, WL-E01).

Sheet Read Me
A1: Workload full-coverage import - Q4 2026
A2: Portal / project | B2: customworkload / NI-2 UIAutomation_Workload_Project2
A3: Built | B3: 2026-10-08
A5: SHEETS
A6: Tasks | B6: Copy of the import rows (the file to import is workload_full_coverage_import.xlsx, Tasks sheet only - Zoho imports rows from EVERY sheet, so never import this workbook). Same 38 columns as the original file, all text.
A7: Scenario Matrix | B7: Planned allocation state per user, month and week, plus the edge-case list.
A8: Assignment Calc | B8: One row per task-owner pair. Yellow cells are the settings to edit (availability, include previous import). Blue = values copied from the Tasks sheet / previous file.
A9: Daily Expected | B9: Expected allocated hours per user per day (1 Oct - 31 Dec 2026). Red > availability, green = availability, amber under, grey weekend.
A10: Weekly Expected | B10: Per user per Mon-Sun week: allocated hrs, available hrs, %, state.
A11: Monthly Expected | B11: Per user per month: hrs, man-days, %, closed/cancelled hrs, day counts per state.
A13: COVERAGE
A14: Users | B14: All 7 portal users + the resource UIAutomation_Workload_Resource + Unassigned.
A15: Allocation states | B15: Every user gets Over, Optimal, Under and Unallocated weeks in each of Oct, Nov, Dec (rotated so users differ on the same day).
A16: Work units | B16: hrs/day, %/day and hrs (total) - all three appear for every user across the quarter.
A17: Spans / edges | B17: Weekend span, single day, weekend-only, zero hours, >100 %, cross-month, resource owner, multi-owner (same / different hrs, %), unassigned with and without hours, no dates.
A18: Field values | B18: All 8 statuses, 4 priorities, 3 billing types, teams A/B/both/none, tags per state, 4 new task lists + Workload CV List, 3 custom-field value sets + blank.
A20: ASSUMPTIONS
A21: Availability | B21: Standard Business Hours: Mon-Fri 09:00-18:00 = 9 h/day for all 7 users, no holiday list (Setup > Business Calendar, checked 08-10-2026). Resource assumed the same.
A22: Status handling | B22: Closed and Cancelled tasks are COUNTED (observed in the report on 08-10-2026). Monthly Expected also shows the value excluding them.
A23: Total hours (hrs) | B23: Spread evenly over the working days of the task range.
A24: %/day | B24: Percent of the 9 h availability.
A25: Previous import | B25: The 12 tasks already imported (UI1-T2..T13) are included in the expected values when Assignment Calc!B2 = 1. UI1-T1 and tasks in other projects are NOT included - filter the report by project NI-2 and use the WL task lists.
A26: VERIFY rows | B26: WL-E03 (weekend-only) and WL-E10 (unassigned with hours) have uncertain product behaviour - check them rather than assert.
A28: IMPORT STEPS
A29: 1 | B29: Add Vishal plreadonly, Vishal liteuser, Vishal customprofile and UIAutomation_Workload_Resource to the project first, otherwise their tasks import unassigned.
A30: 2 | B30: Tasks > ... > Import Tasks > XLS/XLSX, upload workload_full_coverage_import.xlsx (NOT this workbook).
A31: 3 | B31: Select date format dd/MM/yyyy.
A32: 4 | B32: Statuses map 1:1. Users: choose "Map the assigned XLS Users to project users".
A33: 5 | B33: Verify with Daily/Weekly/Monthly Expected.

Sheet Scenario Matrix
A1: User | B1: Oct W1 05 Oct-09 Oct | C1: Oct W2 12 Oct-16 Oct | D1: Oct W3 19 Oct-23 Oct | E1: Oct W4 26 Oct-30 Oct | F1: Nov W1 02 Nov-06 Nov | G1: Nov W2 09 Nov-13 Nov | H1: Nov W3 16 Nov-20 Nov | I1: Nov W4 23 Nov-27 Nov | J1: Dec W1 07 Dec-11 Dec | K1: Dec W2 14 Dec-18 Dec | L1: Dec W3 21 Dec-25 Dec | M1: Dec W4 28 Dec-31 Dec
A2: Vishal workload | B2: Over-allocated 6:00/d + 4:30/d | C2: Optimally allocated 9:00/d | D2: Under-allocated 4:30/d | E2: Unallocated no task | F2: Optimally allocated total 9 h/d | G2: Under-allocated 8:30/d | H2: Unallocated task with 0:00 | I2: Over-allocated 5:00/d + 50 %/d | J2: Under-allocated total 3 h/d | K2: Unallocated no task | L2: Over-allocated total 12 h/d | M2: Optimally allocated total 4.5 h/d + 4:30/d
A3: Vishal PLAdmin | B3: Optimally allocated 100 %/d | C3: Under-allocated 25 %/d | D3: Unallocated no task | E3: Over-allocated 150 %/d | F3: Under-allocated 4:30/d | G3: Unallocated no task | H3: Over-allocated 6:00/d + 4:30/d | I3: Optimally allocated 9:00/d | J3: Unallocated task with 0:00 | K3: Over-allocated 5:00/d + 50 %/d | L3: Optimally allocated total 9 h/d | M3: Under-allocated 8:30/d
A4: vishal PL manager | B4: Under-allocated total 3 h/d | C4: Unallocated no task | D4: Over-allocated total 12 h/d | E4: Optimally allocated total 4.5 h/d + 4:30/d | F4: Unallocated no task | G4: Over-allocated 150 %/d | H4: Optimally allocated 100 %/d | I4: Under-allocated 25 %/d | J4: Over-allocated 6:00/d + 4:30/d | K4: Optimally allocated 9:00/d | L4: Under-allocated 4:30/d | M4: Unallocated no task
A5: Vishal plemployee | B5: Unallocated task with 0:00 | C5: Over-allocated 5:00/d + 50 %/d | D5: Optimally allocated total 9 h/d | E5: Under-allocated 8:30/d | F5: Over-allocated total 12 h/d | G5: Optimally allocated total 4.5 h/d + 4:30/d | H5: Under-allocated total 3 h/d | I5: Unallocated no task | J5: Optimally allocated 100 %/d | K5: Under-allocated 25 %/d | L5: Unallocated no task | M5: Over-allocated 150 %/d
A6: Vishal plreadonly | B6: Over-allocated 6:00/d + 4:30/d | C6: Optimally allocated 9:00/d | D6: Under-allocated 4:30/d | E6: Unallocated no task | F6: Optimally allocated total 9 h/d | G6: Under-allocated 8:30/d | H6: Unallocated task with 0:00 | I6: Over-allocated 5:00/d + 50 %/d | J6: Under-allocated total 3 h/d | K6: Unallocated no task | L6: Over-allocated total 12 h/d | M6: Optimally allocated total 4.5 h/d + 4:30/d
A7: Vishal liteuser | B7: Optimally allocated 100 %/d | C7: Under-allocated 25 %/d | D7: Unallocated no task | E7: Over-allocated 150 %/d | F7: Under-allocated 4:30/d | G7: Unallocated no task | H7: Over-allocated 6:00/d + 4:30/d | I7: Optimally allocated 9:00/d | J7: Unallocated task with 0:00 | K7: Over-allocated 5:00/d + 50 %/d | L7: Optimally allocated total 9 h/d | M7: Under-allocated 8:30/d
A8: Vishal customprofile | B8: Under-allocated total 3 h/d | C8: Unallocated no task | D8: Over-allocated total 12 h/d | E8: Optimally allocated total 4.5 h/d + 4:30/d | F8: Unallocated no task | G8: Over-allocated 150 %/d | H8: Optimally allocated 100 %/d | I8: Under-allocated 25 %/d | J8: Over-allocated 6:00/d + 4:30/d | K8: Optimally allocated 9:00/d | L8: Under-allocated 4:30/d | M8: Unallocated no task
A9: UIAutomation_Workload_Resource | B9: Unallocated task with 0:00 | C9: Over-allocated 5:00/d + 50 %/d | D9: Optimally allocated total 9 h/d | E9: Under-allocated 8:30/d | F9: Over-allocated total 12 h/d | G9: Optimally allocated total 4.5 h/d + 4:30/d | H9: Under-allocated total 3 h/d | I9: Unallocated no task | J9: Optimally allocated 100 %/d | K9: Under-allocated 25 %/d | L9: Unallocated no task | M9: Over-allocated 150 %/d
A11: Edge case | B11: Owners | C11: Unit | D11: Start | E11: Due | F11: Scenario | G11: Expected
A12: WL-E01 Weekend span total hours - Vishal workload | B12: Vishal workload (18) | C12: hrs | D12: 01/10/2026 | E12: 04/10/2026 | F12: Thu-Sun span, 18 h total spread over working days only | G12: 9:00 on Thu 1 Oct and Fri 2 Oct; 0 on Sat/Sun
A13: WL-E02 Single-day total hours - Vishal PLAdmin | B13: Vishal PLAdmin (12) | C13: hrs | D13: 01/10/2026 | E13: 01/10/2026 | F13: Single day task, 12 h total | G13: 12:00 on 1 Oct = 133.33 % (over)
A14: WL-E03 Weekend-only task - vishal PL manager | B14: vishal PL manager (4) | C14: hrs/day | D14: 03/10/2026 | E14: 04/10/2026 | F14: Starts and ends on non-working days (Sat-Sun) | G14: VERIFY: 0 h expected (no working days in range)
A15: WL-E04 Zero-hour owned task - Vishal plemployee | B15: Vishal plemployee (0) | C15: hrs | D15: 01/10/2026 | E15: 02/10/2026 | F15: Owner set, work 00:00 | G15: Task listed under user, 0 h allocated
A16: WL-E05 150 percent per day - Vishal customprofile | B16: Vishal customprofile (150) | C16: %/day | D16: 01/10/2026 | E16: 02/10/2026 | F16: %/day above 100 | G16: 13:30 per day on 1-2 Oct (over)
A17: WL-E06 Cross-month total hours - Vishal plreadonly | B17: Vishal plreadonly (45) | C17: hrs | D17: 30/11/2026 | E17: 04/12/2026 | F17: Mon 30 Nov - Fri 4 Dec, 45 h total | G17: 9:00/day; Nov gets 9 h, Dec gets 36 h
A18: WL-E07 Resource cross-month - UIAutomation_Workload_Resource | B18: UIAutomation_Workload_Resource (9) | C18: hrs/day | D18: 30/11/2026 | E18: 04/12/2026 | F18: Resource as owner, crosses month end | G18: 9:00/day 30 Nov - 4 Dec (optimal)
A19: WL-E08 Multi-owner different hours - Vishal liteuser and Vishal customprofile | B19: Vishal liteuser (6), Vishal customprofile (3) | C19: hrs/day | D19: 01/12/2026 | E19: 04/12/2026 | F19: Two owners, different hrs/day | G19: liteuser 6:00/day, customprofile 3:00/day on 1-4 Dec
A20: WL-E09 Multi-owner percent - Vishal workload, Vishal PLAdmin, vishal PL manager | B20: Vishal workload (50), Vishal PLAdmin (25), vishal PL manager (25) | C20: %/day | D20: 01/12/2026 | E20: 04/12/2026 | F20: Three owners, different %/day | G20: workload 4:30, PLAdmin 2:15, PL manager 2:15 per day on 1-4 Dec
A21: WL-E10 Unassigned task with hours | B21: Unassigned (4) | C21: hrs/day | D21: 05/10/2026 | E21: 09/10/2026 | F21: No owner, 4:00/day | G21: VERIFY: Unassigned User row shows 4:00/day 5-9 Oct (or 0 if hours are dropped without owner)
A22: WL-E11 Unassigned task without hours | B22: Unassigned (0) | C22: hrs | D22: 02/11/2026 | E22: 06/11/2026 | F22: No owner, no work | G22: Unassigned User task count +1, 0 h
A23: WL-E12 No dates task - Vishal workload | B23: Vishal workload (10) | C23: hrs | F23: Owner and 10 h total but no start/due date | G23: Not shown on any date in the Workload Report
A24: WL-E13 Single Friday full day - Vishal liteuser | B24: Vishal liteuser (9) | C24: hrs/day | D24: 02/10/2026 | E24: 02/10/2026 | F24: Single working day | G24: 9:00 on Fri 2 Oct (optimal)
A25: WL-E14 60 percent single day - UIAutomation_Workload_Resource | B25: UIAutomation_Workload_Resource (60) | C25: %/day | D25: 01/10/2026 | E25: 01/10/2026 | F25: Resource, %/day below 100 | G25: 5:24 on 1 Oct (under)
A26: WL-E15 Multi-owner same hours - vishal PL manager and Vishal plemployee | B26: vishal PL manager (4.5), Vishal plemployee (4.5) | C26: hrs/day | D26: 30/11/2026 | E26: 30/11/2026 | F26: Two owners, same hrs/day, single day | G26: 4:30 each on Mon 30 Nov (under)

Sheet Assignment Calc
A1: Availability (hrs/day) | B1: 9 | C1: Source: Setup > Business Calendar > Standard Business Hours (Mon-Fri 09:00-18:00), checked 08-10-2026
A2: Include previous import (1 = yes, 0 = no) | B2: 1 | C2: Previous import = the 12 tasks from the original file (UI1-T2..UI1-T13)
A4: Source | B4: Tasks row | C4: Task name | D4: Owner (report row) | E4: Status | F4: Unit | G4: Owner value | H4: Start | I4: Due | J4: Working days | K4: Hrs / working day | L4: Include | M4: Closed/Cancelled | N4: Hours in range
A5: New file | B5: 2 | C5: =Tasks!A2 -> WL Oct W1 Over-allocated (1 of 2) - Vishal workload | D5: Vishal workload | E5: =Tasks!C2 -> Open | F5: =Tasks!O2 -> hrs/day | G5: 6 | H5: =IF(Tasks!F2="","",DATE(RIGHT(Tasks!F2,4),MID(Tasks!F2,4,2),LEFT(Tasks!F2,2))) -> 46300 | I5: =IF(Tasks!G2="","",DATE(RIGHT(Tasks!G2,4),MID(Tasks!G2,4,2),LEFT(Tasks!G2,2))) -> 46304 | J5: =IF(H5="",0,NETWORKDAYS(H5,I5)) -> 5 | K5: =IF(OR(H5="",J5=0),0,IF(F5="hrs/day",G5,IF(F5="%/day",G5/100*$B$1,G5/J5))) -> 6 | L5: =IF(A5="Previous import",$B$2,1) -> 1 | M5: =IF(OR(E5="Closed",E5="Cancelled"),1,0) -> 0 | N5: =K5*J5*L5 -> 30
A6: New file | B6: 3 | C6: =Tasks!A3 -> WL Oct W1 Over-allocated (2 of 2) - Vishal workload | D6: Vishal workload | E6: =Tasks!C3 -> In Progress | F6: =Tasks!O3 -> hrs/day | G6: 4.5 | H6: =IF(Tasks!F3="","",DATE(RIGHT(Tasks!F3,4),MID(Tasks!F3,4,2),LEFT(Tasks!F3,2))) -> 46300 | I6: =IF(Tasks!G3="","",DATE(RIGHT(Tasks!G3,4),MID(Tasks!G3,4,2),LEFT(Tasks!G3,2))) -> 46304 | J6: =IF(H6="",0,NETWORKDAYS(H6,I6)) -> 5 | K6: =IF(OR(H6="",J6=0),0,IF(F6="hrs/day",G6,IF(F6="%/day",G6/100*$B$1,G6/J6))) -> 4.5 | L6: =IF(A6="Previous import",$B$2,1) -> 1 | M6: =IF(OR(E6="Closed",E6="Cancelled"),1,0) -> 0 | N6: =K6*J6*L6 -> 22.5
